Workbook

Sheet Alignment Between LLMs Raw (O)
A1: GPT
A2: item | B2: domain | C2: wasserstein | D2: alignment | E2: comparison | I2: item | J2: domain | K2: wasserstein | L2: alignment | M2: comparison | Q2: item | R2: domain | S2: wasserstein | T2: alignment | U2: comparison | Y2: item | Z2: domain | AA2: wasserstein | AB2: alignment | AC2: comparison | AG2: item | AH2: domain | AI2: wasserstein | AJ2: alignment | AK2: comparison
A3: Extraversion_1 | B3: Extraversion | C3: 0.63 | D3: 0.8425 | E3: llm_src_en_gpt_vs_llm_tgt_cn_gpt | I3: Extraversion_1 | J3: Extraversion | K3: 0.83 | L3: 0.7925 | M3: llm_src_en_gpt_vs_llm_tgt_es_gpt | Q3: Extraversion_1 | R3: Extraversion | S3: 0.62 | T3: 0.845 | U3: llm_src_en_gpt_vs_llm_tgt_tr_gpt | Y3: Extraversion_1 | Z3: Extraversion | AA3: 0.21 | AB3: 0.9475 | AC3: llm_src_tr_gpt_vs_llm_tgt_es_gpt | AG3: Extraversion_1 | AH3: Extraversion | AI3: 0.2 | AJ3: 0.95 | AK3: llm_src_es_gpt_vs_llm_tgt_cn_gpt
A4: Extraversion_2 | B4: Extraversion | C4: 0.1 | D4: 0.975 | E4: llm_src_en_gpt_vs_llm_tgt_cn_gpt | I4: Extraversion_2 | J4: Extraversion | K4: 0.24 | L4: 0.94 | M4: llm_src_en_gpt_vs_llm_tgt_es_gpt | Q4: Extraversion_2 | R4: Extraversion | S4: 0.07 | T4: 0.9825 | U4: llm_src_en_gpt_vs_llm_tgt_tr_gpt | Y4: Extraversion_2 | Z4: Extraversion | AA4: 0.17 | AB4: 0.9575 | AC4: llm_src_tr_gpt_vs_llm_tgt_es_gpt | AG4: Extraversion_2 | AH4: Extraversion | AI4: 0.14 | AJ4: 0.965 | AK4: llm_src_es_gpt_vs_llm_tgt_cn_gpt
A5: Extraversion_3 | B5: Extraversion | C5: 0.18 | D5: 0.955 | E5: llm_src_en_gpt_vs_llm_tgt_cn_gpt | I5: Extraversion_3 | J5: Extraversion | K5: 0.77 | L5: 0.8075 | M5: llm_src_en_gpt_vs_llm_tgt_es_gpt | Q5: Extraversion_3 | R5: Extraversion | S5: 0.19 | T5: 0.9525 | U5: llm_src_en_gpt_vs_llm_tgt_tr_gpt | Y5: Extraversion_3 | Z5: Extraversion | AA5: 0.96 | AB5: 0.76 | AC5: llm_src_tr_gpt_vs_llm_tgt_es_gpt | AG5: Extraversion_3 | AH5: Extraversion | AI5: 0.95 | AJ5: 0.7625 | AK5: llm_src_es_gpt_vs_llm_tgt_cn_gpt
A6: Extraversion_4 | B6: Extraversion | C6: 0.15 | D6: 0.9625 | E6: llm_src_en_gpt_vs_llm_tgt_cn_gpt | I6: Extraversion_4 | J6: Extraversion | K6: 0.5 | L6: 0.875 | M6: llm_src_en_gpt_vs_llm_tgt_es_gpt | Q6: Extraversion_4 | R6: Extraversion | S6: 0.49 | T6: 0.8775 | U6: llm_src_en_gpt_vs_llm_tgt_tr_gpt | Y6: Extraversion_4 | Z6: Extraversion | AA6: 0.01 | AB6: 0.9975 | AC6: llm_src_tr_gpt_vs_llm_tgt_es_gpt | AG6: Extraversion_4 | AH6: Extraversion | AI6: 0.63 | AJ6: 0.8425 | AK6: llm_src_es_gpt_vs_llm_tgt_cn_gpt
A7: Extraversion_5 | B7: Extraversion | C7: 0.03 | D7: 0.9925 | E7: llm_src_en_gpt_vs_llm_tgt_cn_gpt | I7: Extraversion_5 | J7: Extraversion | K7: 0.14 | L7: 0.965 | M7: llm_src_en_gpt_vs_llm_tgt_es_gpt | Q7: Extraversion_5 | R7: Extraversion | S7: 0.04 | T7: 0.99 | U7: llm_src_en_gpt_vs_llm_tgt_tr_gpt | Y7: Extraversion_5 | Z7: Extraversion | AA7: 0.1 | AB7: 0.975 | AC7: llm_src_tr_gpt_vs_llm_tgt_es_gpt | AG7: Extraversion_5 | AH7: Extraversion | AI7: 0.11 | AJ7: 0.9725 | AK7: llm_src_es_gpt_vs_llm_tgt_cn_gpt
A8: Extraversion_6 | B8: Extraversion | C8: 0.07 | D8: 0.9825 | E8: llm_src_en_gpt_vs_llm_tgt_cn_gpt | I8: Extraversion_6 | J8: Extraversion | K8: 0.06 | L8: 0.985 | M8: llm_src_en_gpt_vs_llm_tgt_es_gpt | Q8: Extraversion_6 | R8: Extraversion | S8: 0.06 | T8: 0.985 | U8: llm_src_en_gpt_vs_llm_tgt_tr_gpt | Y8: Extraversion_6 | Z8: Extraversion | AA8: 0 | AB8: 1 | AC8: llm_src_tr_gpt_vs_llm_tgt_es_gpt | AG8: Extraversion_6 | AH8: Extraversion | AI8: 0.01 | AJ8: 0.9975 | AK8: llm_src_es_gpt_vs_llm_tgt_cn_gpt
A9: Extraversion_7 | B9: Extraversion | C9: 0.15 | D9: 0.9625 | E9: llm_src_en_gpt_vs_llm_tgt_cn_gpt | I9: Extraversion_7 | J9: Extraversion | K9: 0.16 | L9: 0.96 | M9: llm_src_en_gpt_vs_llm_tgt_es_gpt | Q9: Extraversion_7 | R9: Extraversion | S9: 0.37 | T9: 0.9075 | U9: llm_src_en_gpt_vs_llm_tgt_tr_gpt | Y9: Extraversion_7 | Z9: Extraversion | AA9: 0.21 | AB9: 0.9475 | AC9: llm_src_tr_gpt_vs_llm_tgt_es_gpt | AG9: Extraversion_7 | AH9: Extraversion | AI9: 0.01 | AJ9: 0.9975 | AK9: llm_src_es_gpt_vs_llm_tgt_cn_gpt
A10: Extraversion_8 | B10: Extraversion | C10: 0.07 | D10: 0.9825 | E10: llm_src_en_gpt_vs_llm_tgt_cn_gpt | I10: Extraversion_8 | J10: Extraversion | K10: 0.02 | L10: 0.995 | M10: llm_src_en_gpt_vs_llm_tgt_es_gpt | Q10: Extraversion_8 | R10: Extraversion | S10: 0.05 | T10: 0.9875 | U10: llm_src_en_gpt_vs_llm_tgt_tr_gpt | Y10: Extraversion_8 | Z10: Extraversion | AA10: 0.05 | AB10: 0.9875 | AC10: llm_src_tr_gpt_vs_llm_tgt_es_gpt | AG10: Extraversion_8 | AH10: Extraversion | AI10: 0.07 | AJ10: 0.9825 | AK10: llm_src_es_gpt_vs_llm_tgt_cn_gpt
A11: Extraversion_9 | B11: Extraversion | C11: 0.07 | D11: 0.9825 | E11: llm_src_en_gpt_vs_llm_tgt_cn_gpt | I11: Extraversion_9 | J11: Extraversion | K11: 0.17 | L11: 0.9575 | M11: llm_src_en_gpt_vs_llm_tgt_es_gpt | Q11: Extraversion_9 | R11: Extraversion | S11: 0.08 | T11: 0.98 | U11: llm_src_en_gpt_vs_llm_tgt_tr_gpt | Y11: Extraversion_9 | Z11: Extraversion | AA11: 0.11 | AB11: 0.9725 | AC11: llm_src_tr_gpt_vs_llm_tgt_es_gpt | AG11: Extraversion_9 | AH11: Extraversion | AI11: 0.12 | AJ11: 0.97 | AK11: llm_src_es_gpt_vs_llm_tgt_cn_gpt
A12: Extraversion_10 | B12: Extraversion | C12: 0.6 | D12: 0.85 | E12: llm_src_en_gpt_vs_llm_tgt_cn_gpt | I12: Extraversion_10 | J12: Extraversion | K12: 0.63 | L12: 0.8425 | M12: llm_src_en_gpt_vs_llm_tgt_es_gpt | Q12: Extraversion_10 | R12: Extraversion | S12: 0.6 | T12: 0.85 | U12: llm_src_en_gpt_vs_llm_tgt_tr_gpt | Y12: Extraversion_10 | Z12: Extraversion | AA12: 0.03 | AB12: 0.9925 | AC12: llm_src_tr_gpt_vs_llm_tgt_es_gpt | AG12: Extraversion_10 | AH12: Extraversion | AI12: 0.03 | AJ12: 0.9925 | AK12: llm_src_es_gpt_vs_llm_tgt_cn_gpt
A13: Extraversion_11 | B13: Extraversion | C13: 0.23 | D13: 0.9425 | E13: llm_src_en_gpt_vs_llm_tgt_cn_gpt | I13: Extraversion_11 | J13: Extraversion | K13: 0.07 | L13: 0.9825 | M13: llm_src_en_gpt_vs_llm_tgt_es_gpt | Q13: Extraversion_11 | R13: Extraversion | S13: 0.09 | T13: 0.9775 | U13: llm_src_en_gpt_vs_llm_tgt_tr_gpt | Y13: Extraversion_11 | Z13: Extraversion | AA13: 0.02 | AB13: 0.995 | AC13: llm_src_tr_gpt_vs_llm_tgt_es_gpt | AG13: Extraversion_11 | AH13: Extraversion | AI13: 0.3 | AJ13: 0.925 | AK13: llm_src_es_gpt_vs_llm_tgt_cn_gpt
A14: Extraversion_12 | B14: Extraversion | C14: 0.1 | D14: 0.975 | E14: llm_src_en_gpt_vs_llm_tgt_cn_gpt | I14: Extraversion_12 | J14: Extraversion | K14: 0.28 | L14: 0.93 | M14: llm_src_en_gpt_vs_llm_tgt_es_gpt | Q14: Extraversion_12 | R14: Extraversion | S14: 0.1 | T14: 0.975 | U14: llm_src_en_gpt_vs_llm_tgt_tr_gpt | Y14: Extraversion_12 | Z14: Extraversion | AA14: 0.24 | AB14: 0.94 | AC14: llm_src_tr_gpt_vs_llm_tgt_es_gpt | AG14: Extraversion_12 | AH14: Extraversion | AI14: 0.24 | AJ14: 0.94 | AK14: llm_src_es_gpt_vs_llm_tgt_cn_gpt
... A62: Open_Mindedness_12 | B62: Open_Mindedness | C62: 0.71 | D62: 0.8225 | E62: llm_src_en_gpt_vs_llm_tgt_cn_gpt | I62: Open_Mindedness_12 | J62: Open_Mindedness | K62: 0.24 | L62: 0.94 | M62: llm_src_en_gpt_vs_llm_tgt_es_gpt | Q62: Open_Mindedness_12 | R62: Open_Mindedness | S62: 0.66 | T62: 0.835 | U62: llm_src_en_gpt_vs_llm_tgt_tr_gpt | Y62: Open_Mindedness_12 | Z62: Open_Mindedness | AA62: 0.9 | AB62: 0.775 | AC62: llm_src_tr_gpt_vs_llm_tgt_es_gpt | AG62: Open_Mindedness_12 | AH62: Open_Mindedness | AI62: 0.95 | AJ62: 0.7625 | AK62: llm_src_es_gpt_vs_llm_tgt_cn_gpt
A64: DeepSeek
A65: item | B65: domain | C65: wasserstein | D65: alignment | E65: comparison | I65: item | J65: domain | K65: wasserstein | L65: alignment | M65: comparison | Q65: item | R65: domain | S65: wasserstein | T65: alignment | U65: comparison | Y65: item | Z65: domain | AA65: wasserstein | AB65: alignment | AC65: comparison
A66: Extraversion_1 | B66: Extraversion | C66: 0 | D66: 1 | E66: llm_src_en_DeepSeek_vs_llm_tgt_cn_DeepSeek | I66: Extraversion_1 | J66: Extraversion | K66: 0 | L66: 1 | M66: llm_src_en_DeepSeek_vs_llm_tgt_es_DeepSeek | Q66: Extraversion_1 | R66: Extraversion | S66: 3 | T66: 0.25 | U66: llm_src_en_DeepSeek_vs_llm_tgt_tr_DeepSeek | Y66: Extraversion_1 | Z66: Extraversion | AA66: 3 | AB66: 0.25 | AC66: llm_src_tr_DeepSeek_vs_llm_tgt_es_DeepSeek | AG66: item | AH66: domain | AI66: wasserstein | AJ66: alignment | AK66: comparison
A67: Extraversion_2 | B67: Extraversion | C67: 0 | D67: 1 | E67: llm_src_en_DeepSeek_vs_llm_tgt_cn_DeepSeek | I67: Extraversion_2 | J67: Extraversion | K67: 0 | L67: 1 | M67: llm_src_en_DeepSeek_vs_llm_tgt_es_DeepSeek | Q67: Extraversion_2 | R67: Extraversion | S67: 0.01 | T67: 0.9975 | U67: llm_src_en_DeepSeek_vs_llm_tgt_tr_DeepSeek | Y67: Extraversion_2 | Z67: Extraversion | AA67: 0.01 | AB67: 0.9975 | AC67: llm_src_tr_DeepSeek_vs_llm_tgt_es_DeepSeek | AG67: Extraversion_1 | AH67: Extraversion | AI67: 0 | AJ67: 1 | AK67: llm_src_cn_DeepSeek_vs_llm_tgt_es_DeepSeek
A68: Extraversion_3 | B68: Extraversion | C68: 0 | D68: 1 | E68: llm_src_en_DeepSeek_vs_llm_tgt_cn_DeepSeek | I68: Extraversion_3 | J68: Extraversion | K68: 0 | L68: 1 | M68: llm_src_en_DeepSeek_vs_llm_tgt_es_DeepSeek | Q68: Extraversion_3 | R68: Extraversion | S68: 0 | T68: 1 | U68: llm_src_en_DeepSeek_vs_llm_tgt_tr_DeepSeek | Y68: Extraversion_3 | Z68: Extraversion | AA68: 0 | AB68: 1 | AC68: llm_src_tr_DeepSeek_vs_llm_tgt_es_DeepSeek | AG68: Extraversion_2 | AH68: Extraversion | AI68: 0 | AJ68: 1 | AK68: llm_src_cn_DeepSeek_vs_llm_tgt_es_DeepSeek
A69: Extraversion_4 | B69: Extraversion | C69: 0 | D69: 1 | E69: llm_src_en_DeepSeek_vs_llm_tgt_cn_DeepSeek | I69: Extraversion_4 | J69: Extraversion | K69: 0 | L69: 1 | M69: llm_src_en_DeepSeek_vs_llm_tgt_es_DeepSeek | Q69: Extraversion_4 | R69: Extraversion | S69: 0 | T69: 1 | U69: llm_src_en_DeepSeek_vs_llm_tgt_tr_DeepSeek | Y69: Extraversion_4 | Z69: Extraversion | AA69: 0 | AB69: 1 | AC69: llm_src_tr_DeepSeek_vs_llm_tgt_es_DeepSeek | AG69: Extraversion_3 | AH69: Extraversion | AI69: 0 | AJ69: 1 | AK69: llm_src_cn_DeepSeek_vs_llm_tgt_es_DeepSeek
A70: Extraversion_5 | B70: Extraversion | C70: 1 | D70: 0.75 | E70: llm_src_en_DeepSeek_vs_llm_tgt_cn_DeepSeek | I70: Extraversion_5 | J70: Extraversion | K70: 0 | L70: 1 | M70: llm_src_en_DeepSeek_vs_llm_tgt_es_DeepSeek | Q70: Extraversion_5 | R70: Extraversion | S70: 0.01 | T70: 0.9975 | U70: llm_src_en_DeepSeek_vs_llm_tgt_tr_DeepSeek | Y70: Extraversion_5 | Z70: Extraversion | AA70: 0.01 | AB70: 0.9975 | AC70: llm_src_tr_DeepSeek_vs_llm_tgt_es_DeepSeek | AG70: Extraversion_4 | AH70: Extraversion | AI70: 0 | AJ70: 1 | AK70: llm_src_cn_DeepSeek_vs_llm_tgt_es_DeepSeek
A71: Extraversion_6 | B71: Extraversion | C71: 0 | D71: 1 | E71: llm_src_en_DeepSeek_vs_llm_tgt_cn_DeepSeek | I71: Extraversion_6 | J71: Extraversion | K71: 0 | L71: 1 | M71: llm_src_en_DeepSeek_vs_llm_tgt_es_DeepSeek | Q71: Extraversion_6 | R71: Extraversion | S71: 0.01 | T71: 0.9975 | U71: llm_src_en_DeepSeek_vs_llm_tgt_tr_DeepSeek | Y71: Extraversion_6 | Z71: Extraversion | AA71: 0.01 | AB71: 0.9975 | AC71: llm_src_tr_DeepSeek_vs_llm_tgt_es_DeepSeek | AG71: Extraversion_5 | AH71: Extraversion | AI71: 1 | AJ71: 0.75 | AK71: llm_src_cn_DeepSeek_vs_llm_tgt_es_DeepSeek
A72: Extraversion_7 | B72: Extraversion | C72: 0 | D72: 1 | E72: llm_src_en_DeepSeek_vs_llm_tgt_cn_DeepSeek | I72: Extraversion_7 | J72: Extraversion | K72: 0 | L72: 1 | M72: llm_src_en_DeepSeek_vs_llm_tgt_es_DeepSeek | Q72: Extraversion_7 | R72: Extraversion | S72: 0 | T72: 1 | U72: llm_src_en_DeepSeek_vs_llm_tgt_tr_DeepSeek | Y72: Extraversion_7 | Z72: Extraversion | AA72: 0 | AB72: 1 | AC72: llm_src_tr_DeepSeek_vs_llm_tgt_es_DeepSeek | AG72: Extraversion_6 | AH72: Extraversion | AI72: 0 | AJ72: 1 | AK72: llm_src_cn_DeepSeek_vs_llm_tgt_es_DeepSeek
A73: Extraversion_8 | B73: Extraversion | C73: 0 | D73: 1 | E73: llm_src_en_DeepSeek_vs_llm_tgt_cn_DeepSeek | I73: Extraversion_8 | J73: Extraversion | K73: 0 | L73: 1 | M73: llm_src_en_DeepSeek_vs_llm_tgt_es_DeepSeek | Q73: Extraversion_8 | R73: Extraversion | S73: 0 | T73: 1 | U73: llm_src_en_DeepSeek_vs_llm_tgt_tr_DeepSeek | Y73: Extraversion_8 | Z73: Extraversion | AA73: 0 | AB73: 1 | AC73: llm_src_tr_DeepSeek_vs_llm_tgt_es_DeepSeek | AG73: Extraversion_7 | AH73: Extraversion | AI73: 0 | AJ73: 1 | AK73: llm_src_cn_DeepSeek_vs_llm_tgt_es_DeepSeek
A74: Extraversion_9 | B74: Extraversion | C74: 0 | D74: 1 | E74: llm_src_en_DeepSeek_vs_llm_tgt_cn_DeepSeek | I74: Extraversion_9 | J74: Extraversion | K74: 0 | L74: 1 | M74: llm_src_en_DeepSeek_vs_llm_tgt_es_DeepSeek | Q74: Extraversion_9 | R74: Extraversion | S74: 0.01 | T74: 0.9975 | U74: llm_src_en_DeepSeek_vs_llm_tgt_tr_DeepSeek | Y74: Extraversion_9 | Z74: Extraversion | AA74: 0.01 | AB74: 0.9975 | AC74: llm_src_tr_DeepSeek_vs_llm_tgt_es_DeepSeek | AG74: Extraversion_8 | AH74: Extraversion | AI74: 0 | AJ74: 1 | AK74: llm_src_cn_DeepSeek_vs_llm_tgt_es_DeepSeek
A75: Extraversion_10 | B75: Extraversion | C75: 1 | D75: 0.75 | E75: llm_src_en_DeepSeek_vs_llm_tgt_cn_DeepSeek | I75: Extraversion_10 | J75: Extraversion | K75: 1 | L75: 0.75 | M75: llm_src_en_DeepSeek_vs_llm_tgt_es_DeepSeek | Q75: Extraversion_10 | R75: Extraversion | S75: 0.01 | T75: 0.9975 | U75: llm_src_en_DeepSeek_vs_llm_tgt_tr_DeepSeek | Y75: Extraversion_10 | Z75: Extraversion | AA75: 0.99 | AB75: 0.7525 | AC75: llm_src_tr_DeepSeek_vs_llm_tgt_es_DeepSeek | AG75: Extraversion_9 | AH75: Extraversion | AI75: 0 | AJ75: 1 | AK75: llm_src_cn_DeepSeek_vs_llm_tgt_es_DeepSeek
A76: Extraversion_11 | B76: Extraversion | C76: 1 | D76: 0.75 | E76: llm_src_en_DeepSeek_vs_llm_tgt_cn_DeepSeek | I76: Extraversion_11 | J76: Extraversion | K76: 0 | L76: 1 | M76: llm_src_en_DeepSeek_vs_llm_tgt_es_DeepSeek | Q76: Extraversion_11 | R76: Extraversion | S76: 0 | T76: 1 | U76: llm_src_en_DeepSeek_vs_llm_tgt_tr_DeepSeek | Y76: Extraversion_11 | Z76: Extraversion | AA76: 0 | AB76: 1 | AC76: llm_src_tr_DeepSeek_vs_llm_tgt_es_DeepSeek | AG76: Extraversion_10 | AH76: Extraversion | AI76: 0 | AJ76: 1 | AK76: llm_src_cn_DeepSeek_vs_llm_tgt_es_DeepSeek
A77: Extraversion_12 | B77: Extraversion | C77: 0 | D77: 1 | E77: llm_src_en_DeepSeek_vs_llm_tgt_cn_DeepSeek | I77: Extraversion_12 | J77: Extraversion | K77: 0 | L77: 1 | M77: llm_src_en_DeepSeek_vs_llm_tgt_es_DeepSeek | Q77: Extraversion_12 | R77: Extraversion | S77: 0.01 | T77: 0.9975 | U77: llm_src_en_DeepSeek_vs_llm_tgt_tr_DeepSeek | Y77: Extraversion_12 | Z77: Extraversion | AA77: 0.01 | AB77: 0.9975 | AC77: llm_src_tr_DeepSeek_vs_llm_tgt_es_DeepSeek | AG77: Extraversion_11 | AH77: Extraversion | AI77: 1 | AJ77: 0.75 | AK77: llm_src_cn_DeepSeek_vs_llm_tgt_es_DeepSeek
A78: Agreeableness_1 | B78: Agreeableness | C78: 1 | D78: 0.75 | E78: llm_src_en_DeepSeek_vs_llm_tgt_cn_DeepSeek | I78: Agreeableness_1 | J78: Agreeableness | K78: 1 | L78: 0.75 | M78: llm_src_en_DeepSeek_vs_llm_tgt_es_DeepSeek | Q78: Agreeableness_1 | R78: Agreeableness | S78: 1 | T78: 0.75 | U78: llm_src_en_DeepSeek_vs_llm_tgt_tr_DeepSeek | Y78: Agreeableness_1 | Z78: Agreeableness | AA78: 0 | AB78: 1 | AC78: llm_src_tr_DeepSeek_vs_llm_tgt_es_DeepSeek | AG78: Extraversion_12 | AH78: Extraversion | AI78: 0 | AJ78: 1 | AK78: llm_src_cn_DeepSeek_vs_llm_tgt_es_DeepSeek
... A125: Open_Mindedness_12 | B125: Open_Mindedness | C125: 0 | D125: 1 | E125: llm_src_en_DeepSeek_vs_llm_tgt_cn_DeepSeek | I125: Open_Mindedness_12 | J125: Open_Mindedness | K125: 0 | L125: 1 | M125: llm_src_en_DeepSeek_vs_llm_tgt_es_DeepSeek | Q125: Open_Mindedness_12 | R125: Open_Mindedness | S125: 0.99 | T125: 0.7525 | U125: llm_src_en_DeepSeek_vs_llm_tgt_tr_DeepSeek | Y125: Open_Mindedness_12 | Z125: Open_Mindedness | AA125: 0.99 | AB125: 0.7525 | AC125: llm_src_tr_DeepSeek_vs_llm_tgt_es_DeepSeek | AG125: Open_Mindedness_11 | AH125: Open_Mindedness | AI125: 0 | AJ125: 1 | AK125: llm_src_cn_DeepSeek_vs_llm_tgt_es_DeepSeek
AG126: Open_Mindedness_12 | AH126: Open_Mindedness | AI126: 0 | AJ126: 1 | AK126: llm_src_cn_DeepSeek_vs_llm_tgt_es_DeepSeek
A127: Mistral
A128: item | B128: domain | C128: wasserstein | D128: alignment | E128: comparison | I128: item | J128: domain | K128: wasserstein | L128: alignment | M128: comparison | Q128: item | R128: domain | S128: wasserstein | T128: alignment | U128: comparison | Y128: item | Z128: domain | AA128: wasserstein | AB128: alignment | AC128: comparison | AG128: item | AH128: domain | AI128: wasserstein | AJ128: alignment | AK128: comparison
A129: Extraversion_1 | B129: Extraversion | C129: 0.06 | D129: 0.985 | E129: llm_src_en_Mistral_vs_llm_tgt_cn_Mistral | I129: Extraversion_1 | J129: Extraversion | K129: 0.52 | L129: 0.87 | M129: llm_src_en_Mistral_vs_llm_tgt_es_Mistral | Q129: Extraversion_1 | R129: Extraversion | S129: 0.06 | T129: 0.985 | U129: llm_src_en_Mistral_vs_llm_tgt_tr_Mistral | Y129: Extraversion_1 | Z129: Extraversion | AA129: 0.58 | AB129: 0.855 | AC129: llm_src_es_Mistral_vs_llm_tgt_tr_Mistral | AG129: Extraversion_1 | AH129: Extraversion | AI129: 0.58 | AJ129: 0.855 | AK129: llm_src_cn_Mistral_vs_llm_tgt_es_Mistral
A130: Extraversion_2 | B130: Extraversion | C130: 0.06 | D130: 0.985 | E130: llm_src_en_Mistral_vs_llm_tgt_cn_Mistral | I130: Extraversion_2 | J130: Extraversion | K130: 0.21 | L130: 0.9475 | M130: llm_src_en_Mistral_vs_llm_tgt_es_Mistral | Q130: Extraversion_2 | R130: Extraversion | S130: 0.48 | T130: 0.88 | U130: llm_src_en_Mistral_vs_llm_tgt_tr_Mistral | Y130: Extraversion_2 | Z130: Extraversion | AA130: 0.27 | AB130: 0.9325 | AC130: llm_src_es_Mistral_vs_llm_tgt_tr_Mistral | AG130: Extraversion_2 | AH130: Extraversion | AI130: 0.15 | AJ130: 0.9625 | AK130: llm_src_cn_Mistral_vs_llm_tgt_es_Mistral
A131: Extraversion_3 | B131: Extraversion | C131: 0.14 | D131: 0.965 | E131: llm_src_en_Mistral_vs_llm_tgt_cn_Mistral | I131: Extraversion_3 | J131: Extraversion | K131: 0.44 | L131: 0.89 | M131: llm_src_en_Mistral_vs_llm_tgt_es_Mistral | Q131: Extraversion_3 | R131: Extraversion | S131: 0.73 | T131: 0.8175 | U131: llm_src_en_Mistral_vs_llm_tgt_tr_Mistral | Y131: Extraversion_3 | Z131: Extraversion | AA131: 0.29 | AB131: 0.9275 | AC131: llm_src_es_Mistral_vs_llm_tgt_tr_Mistral | AG131: Extraversion_3 | AH131: Extraversion | AI131: 0.3 | AJ131: 0.925 | AK131: llm_src_cn_Mistral_vs_llm_tgt_es_Mistral
A132: Extraversion_4 | B132: Extraversion | C132: 0.02 | D132: 0.995 | E132: llm_src_en_Mistral_vs_llm_tgt_cn_Mistral | I132: Extraversion_4 | J132: Extraversion | K132: 0.19 | L132: 0.9525 | M132: llm_src_en_Mistral_vs_llm_tgt_es_Mistral | Q132: Extraversion_4 | R132: Extraversion | S132: 0.37 | T132: 0.9075 | U132: llm_src_en_Mistral_vs_llm_tgt_tr_Mistral | Y132: Extraversion_4 | Z132: Extraversion | AA132: 0.18 | AB132: 0.955 | AC132: llm_src_es_Mistral_vs_llm_tgt_tr_Mistral | AG132: Extraversion_4 | AH132: Extraversion | AI132: 0.17 | AJ132: 0.9575 | AK132: llm_src_cn_Mistral_vs_llm_tgt_es_Mistral
A133: Extraversion_5 | B133: Extraversion | C133: 0.11 | D133: 0.9725 | E133: llm_src_en_Mistral_vs_llm_tgt_cn_Mistral | I133: Extraversion_5 | J133: Extraversion | K133: 0.28 | L133: 0.93 | M133: llm_src_en_Mistral_vs_llm_tgt_es_Mistral | Q133: Extraversion_5 | R133: Extraversion | S133: 0.3 | T133: 0.925 | U133: llm_src_en_Mistral_vs_llm_tgt_tr_Mistral | Y133: Extraversion_5 | Z133: Extraversion | AA133: 0.02 | AB133: 0.995 | AC133: llm_src_es_Mistral_vs_llm_tgt_tr_Mistral | AG133: Extraversion_5 | AH133: Extraversion | AI133: 0.39 | AJ133: 0.9025 | AK133: llm_src_cn_Mistral_vs_llm_tgt_es_Mistral
A134: Extraversion_6 | B134: Extraversion | C134: 0.05 | D134: 0.9875 | E134: llm_src_en_Mistral_vs_llm_tgt_cn_Mistral | I134: Extraversion_6 | J134: Extraversion | K134: 0.34 | L134: 0.915 | M134: llm_src_en_Mistral_vs_llm_tgt_es_Mistral | Q134: Extraversion_6 | R134: Extraversion | S134: 0.19 | T134: 0.9525 | U134: llm_src_en_Mistral_vs_llm_tgt_tr_Mistral | Y134: Extraversion_6 | Z134: Extraversion | AA134: 0.15 | AB134: 0.9625 | AC134: llm_src_es_Mistral_vs_llm_tgt_tr_Mistral | AG134: Extraversion_6 | AH134: Extraversion | AI134: 0.29 | AJ134: 0.9275 | AK134: llm_src_cn_Mistral_vs_llm_tgt_es_Mistral
...

Sheet Alignment by Domain Summary (O)
A1: GPT LLM vs Human Alignment
A2: Domain | B2: English | C2: Spanish | D2: Chinese | E2: Turkish | G2: *Alignment is the average alignment score over the domain
A3: Agreeableness | B3: 0.68680667 | C3: 0.74960406 | D3: 0.64644417 | E3: 0.73736871
A4: Conscientiousness | B4: 0.76721128 | C4: 0.81534104 | D4: 0.69274945 | E4: 0.8094876
A5: Extraversion | B5: 0.73978631 | C5: 0.81109366 | D5: 0.74701043 | E5: 0.79343043
A6: Negative Emotionality | B6: 0.72052452 | C6: 0.70791085 | D6: 0.69941853 | E6: 0.80999726
A7: Open Mindedness | B7: 0.59664188 | C7: 0.76496691 | D7: 0.66814642 | E7: 0.77197119
A9: DeepSeek LLM vs Human Alignment
A10: Domain | B10: English | C10: Spanish | D10: Chinese | E10: Turkish
A11: Agreeableness | B11: 0.61153537 | C11: 0.78452225 | D11: 0.67938087 | E11: 0.68584245
A12: Conscientiousness | B12: 0.71717578 | C12: 0.75861693 | D12: 0.714034 | E12: 0.75637536
A13: Extraversion | B13: 0.69640943 | C13: 0.78973967 | D13: 0.76060669 | E13: 0.76287473
A14: Negative Emotionality | B14: 0.65534566 | C14: 0.71380526 | D14: 0.69212963 | E14: 0.77419675
A15: Open Mindedness | B15: 0.57080654 | C15: 0.79701134 | D15: 0.66286622 | E15: 0.62460567
A17: Mistral LLM vs Human Alignment
A18: Domain | B18: English | C18: Spanish | D18: Chinese | E18: Turkish
A19: Agreeableness | B19: 0.72626675 | C19: 0.64460006 | D19: 0.71199627 | E19: 0.64075219
A20: Conscientiousness | B20: 0.73849611 | C20: 0.76929392 | D20: 0.70952771 | E20: 0.73158735
A21: Extraversion | B21: 0.69324826 | C21: 0.71886453 | D21: 0.71404022 | E21: 0.72162883
A22: Negative Emotionality | B22: 0.73009646 | C22: 0.65817554 | D22: 0.71069444 | E22: 0.74924553
A23: Open Mindedness | B23: 0.72894962 | C23: 0.70296139 | D23: 0.74918498 | E23: 0.6804773

Sheet Cronbach's Alpha Summary (O)
A1: GPT
A2: Domain | B2: English | C2: Spanish | D2: Chinese | E2: Turkish
A3: Extraversion | B3: 0.88691313 | C3: 0.80692119 | D3: 0.66343892 | E3: 0.49023569
A4: Agreeableness | B4: 0.68815636 | C4: 0.61530928 | D4: 0.91828574 | E4: 0.67821802
A5: Conscientiousness | B5: 0.85955403 | C5: 0.83977677 | D5: 0.72188424 | E5: 0.82400547
A6: Negative_Emotionality | B6: 0.89107839 | C6: 0.067567568 | D6: 0.79969287 | E6: 0.68133574
A7: Open_Mindedness | B7: 0.77001361 | C7: 0.64413432 | D7: 0.74205883 | E7: 0.90169595
A9: DeepSeek
A10: Domain | B10: English | C10: Spanish | D10: Chinese | E10: Turkish
A11: Extraversion | B11: *Failed due to lack of data variation
A12: Agreeableness
A13: Conscientiousness
A14: Negative_Emotionality
A15: Open_Mindedness
A17: Mistral
A18: Domain | B18: English | C18: Spanish | D18: Chinese | E18: Turkish
A19: Extraversion | B19: 0.046227023 | C19: 0.031337828 | D19: 0.094726115 | E19: -0.83329535
A20: Agreeableness | B20: -0.47848059 | C20: -1.2830069 | D20: -1.0887255 | E20: -0.89205844
A21: Conscientiousness | B21: 0.20521994 | C21: 0.70964952 | D21: 0.071919266 | E21: 0.49953721
A22: Negative_Emotionality | B22: 0.54879865 | C22: 0.72445597 | D22: 0.35925227 | E22: 0.58238641
A23: Open_Mindedness | B23: -0.84818182 | C23: -1.5091208 | D23: -0.43752859 | E23: -0.83879958

Sheet Alignment Between LLMs (O)
A1: GPT
A2: Domain | B2: English v. Chinese | C2: English v. Spanish | D2: English v. Turkish | E2: Spanish v. Turkish | F2: Spanish v. Chinese
A3: Extraversion | B3: =AVERAGE('Alignment Between LLMs Raw (O)'!D3:D14) -> 0.95041667 | C3: =AVERAGE('Alignment Between LLMs Raw (O)'!L3:L14) -> 0.919375 | D3: =AVERAGE('Alignment Between LLMs Raw (O)'!T3:T14) -> 0.9425 | E3: =AVERAGE('Alignment Between LLMs Raw (O)'!AB3:AB14) -> 0.95604167 | F3: =AVERAGE('Alignment Between LLMs Raw (O)'!AJ3:AJ14) -> 0.94145833
A4: Agreeableness | B4: =AVERAGE('Alignment Between LLMs Raw (O)'!D15:D26) -> 0.94479167 | C4: =AVERAGE('Alignment Between LLMs Raw (O)'!L15:L26) -> 0.90916667 | D4: =AVERAGE('Alignment Between LLMs Raw (O)'!T15:T26) -> 0.969375 | E4: =AVERAGE('Alignment Between LLMs Raw (O)'!AB15:AB26) -> 0.88854167 | F4: =AVERAGE('Alignment Between LLMs Raw (O)'!AJ15:AJ26) -> 0.89395833
A5: Conscientiousness | B5: =AVERAGE('Alignment Between LLMs Raw (O)'!D27:D38) -> 0.95895833 | C5: =AVERAGE('Alignment Between LLMs Raw (O)'!L27:L38) -> 0.94270833 | D5: =AVERAGE('Alignment Between LLMs Raw (O)'!T27:T38) -> 0.92104167 | E5: =AVERAGE('Alignment Between LLMs Raw (O)'!AB27:AB38) -> 0.9425 | F5: =AVERAGE('Alignment Between LLMs Raw (O)'!AJ27:AJ38) -> 0.92541667
A6: Negative Emotionality | B6: =AVERAGE('Alignment Between LLMs Raw (O)'!D39:D50) -> 0.92833333 | C6: =AVERAGE('Alignment Between LLMs Raw (O)'!L39:L50) -> 0.94729167 | D6: =AVERAGE('Alignment Between LLMs Raw (O)'!T39:T50) -> 0.96229167 | E6: =AVERAGE('Alignment Between LLMs Raw (O)'!AB39:AB50) -> 0.94708333 | F6: =AVERAGE('Alignment Between LLMs Raw (O)'!AJ39:AJ50) -> 0.95854167
A7: Open Mindedness | B7: =AVERAGE('Alignment Between LLMs Raw (O)'!D51:D62) -> 0.88125 | C7: =AVERAGE('Alignment Between LLMs Raw (O)'!L51:L62) -> 0.95416667 | D7: =AVERAGE('Alignment Between LLMs Raw (O)'!T51:T62) -> 0.816875 | E7: =AVERAGE('Alignment Between LLMs Raw (O)'!AB51:AB62) -> 0.806875 | F7: =AVERAGE('Alignment Between LLMs Raw (O)'!AJ51:AJ62) -> 0.87375
A9: DeepSeek
A10: Domain | B10: English v. Chinese | C10: English v. Spanish | D10: English v. Turkish | E10: Spanish v. Turkish | F10: Spanish v. Chinese
A11: Extraversion | B11: =AVERAGE('Alignment Between LLMs Raw (O)'!D66:D77) -> 0.9375 | C11: =AVERAGE('Alignment Between LLMs Raw (O)'!L66:L77) -> 0.97916667 | D11: =AVERAGE('Alignment Between LLMs Raw (O)'!T66:T77) -> 0.93625 | E11: =AVERAGE('Alignment Between LLMs Raw (O)'!AB66:AB77) -> 0.91583333 | F11: =AVERAGE('Alignment Between LLMs Raw (O)'!AJ67:AJ78) -> 0.95833333
A12: Agreeableness | B12: =AVERAGE('Alignment Between LLMs Raw (O)'!D78:D89) -> 0.8125 | C12: =AVERAGE('Alignment Between LLMs Raw (O)'!L78:L89) -> 0.9375 | D12: =AVERAGE('Alignment Between LLMs Raw (O)'!T78:T89) -> 0.9375 | E12: =AVERAGE('Alignment Between LLMs Raw (O)'!AB78:AB89) -> 0.95791667 | F12: =AVERAGE('Alignment Between LLMs Raw (O)'!AJ79:AJ90) -> 0.875
A13: Conscientiousness | B13: =AVERAGE('Alignment Between LLMs Raw (O)'!D90:D101) -> 0.9375 | C13: =AVERAGE('Alignment Between LLMs Raw (O)'!L90:L101) -> 0.95833333 | D13: =AVERAGE('Alignment Between LLMs Raw (O)'!T90:T101) -> 0.89604167 | E13: =AVERAGE('Alignment Between LLMs Raw (O)'!AB90:AB101) -> 0.89645833 | F13: =AVERAGE('Alignment Between LLMs Raw (O)'!AJ91:AJ102) -> 0.9375
A14: Negative Emotionality | B14: =AVERAGE('Alignment Between LLMs Raw (O)'!D102:D113) -> 0.97916667 | C14: =AVERAGE('Alignment Between LLMs Raw (O)'!L102:L113) -> 0.9375 | D14: =AVERAGE('Alignment Between LLMs Raw (O)'!T102:T113) -> 0.93708333 | E14: =AVERAGE('Alignment Between LLMs Raw (O)'!AB102:AB113) -> 0.9575 | F14: =AVERAGE('Alignment Between LLMs Raw (O)'!AJ103:AJ114) -> 0.91666667
A15: Open Mindedness | B15: =AVERAGE('Alignment Between LLMs Raw (O)'!D114:D125) -> 0.85416667 | C15: =AVERAGE('Alignment Between LLMs Raw (O)'!L114:L125) -> 0.89583333 | D15: =AVERAGE('Alignment Between LLMs Raw (O)'!T114:T125) -> 0.936875 | E15: =AVERAGE('Alignment Between LLMs Raw (O)'!AB114:AB125) -> 0.916875 | F15: =AVERAGE('Alignment Between LLMs Raw (O)'!AJ115:AJ126) -> 0.91666667
A17: Mistral
A18: Domain | B18: English v. Chinese | C18: English v. Spanish | D18: English v. Turkish | E18: Spanish v. Turkish | F18: Spanish v. Chinese
A19: Extraversion | B19: =AVERAGE('Alignment Between LLMs Raw (O)'!D129:D140) -> 0.971875 | C19: =AVERAGE('Alignment Between LLMs Raw (O)'!L129:L140) -> 0.915 | D19: =AVERAGE('Alignment Between LLMs Raw (O)'!T129:T140) -> 0.91791667 | E19: =AVERAGE('Alignment Between LLMs Raw (O)'!AB129:AB140) -> 0.94041667 | F19: =AVERAGE('Alignment Between LLMs Raw (O)'!AJ129:AJ140) -> 0.91645833
A20: Agreeableness | B20: =AVERAGE('Alignment Between LLMs Raw (O)'!D141:D152) -> 0.971875 | C20: =AVERAGE('Alignment Between LLMs Raw (O)'!L141:L152) -> 0.92604167 | D20: =AVERAGE('Alignment Between LLMs Raw (O)'!T141:T152) -> 0.91520833 | E20: =AVERAGE('Alignment Between LLMs Raw (O)'!AB141:AB152) -> 0.94291667 | F20: =AVERAGE('Alignment Between LLMs Raw (O)'!AJ141:AJ152) -> 0.92708333
A21: Conscientiousness | B21: =AVERAGE('Alignment Between LLMs Raw (O)'!D153:D164) -> 0.97333333 | C21: =AVERAGE('Alignment Between LLMs Raw (O)'!L153:L164) -> 0.93354167 | D21: =AVERAGE('Alignment Between LLMs Raw (O)'!T153:T164) -> 0.931875 | E21: =AVERAGE('Alignment Between LLMs Raw (O)'!AB153:AB164) -> 0.93791667 | F21: =AVERAGE('Alignment Between LLMs Raw (O)'!AJ153:AJ164) -> 0.91854167
A22: Negative Emotionality | B22: =AVERAGE('Alignment Between LLMs Raw (O)'!D165:D176) -> 0.96125 | C22: =AVERAGE('Alignment Between LLMs Raw (O)'!L165:L176) -> 0.91208333 | D22: =AVERAGE('Alignment Between LLMs Raw (O)'!T165:T176) -> 0.91770833 | E22: =AVERAGE('Alignment Between LLMs Raw (O)'!AB165:AB176) -> 0.946875 | F22: =AVERAGE('Alignment Between LLMs Raw (O)'!AJ165:AJ176) -> 0.915
A23: Open Mindedness | B23: =AVERAGE('Alignment Between LLMs Raw (O)'!D177:D188) -> 0.98770833 | C23: =AVERAGE('Alignment Between LLMs Raw (O)'!L177:L188) -> 0.93729167 | D23: =AVERAGE('Alignment Between LLMs Raw (O)'!T177:T188) -> 0.916875 | E23: =AVERAGE('Alignment Between LLMs Raw (O)'!AB177:AB188) -> 0.93 | F23: =AVERAGE('Alignment Between LLMs Raw (O)'!AJ177:AJ188) -> 0.92833333

Sheet Model Similarity (N)
A1: x_1 | B1: x_2 | C1: similarity
A2: Qwen3-14B.cn | B2: Qwen3-14B.en | C2: 0.57367811 | G2: Notes
A3: Qwen3-4B.cn | B3: Qwen3-4B.en | C3: 0.35312509 | G3: The highest similarity scores appear between Qwen models, both at 4B and 14B parameters
A4: Qwen3-8B.cn | B4: Qwen3-8B.en | C4: 0.15656715 | G4: There doesn't appear to be much consistency between language and similarity (i.e. the results from Llama-3.2-3B.cn are not more likely to be similar to Ministral-3-14B.cn just because both are in Chinese)
A5: Qwen3-14B.en | B5: Qwen3-4B.en | C5: 0.13984549 | G5: *Similarity based on Hausdorff distance
A6: Qwen3-14B.cn | B6: Qwen3-4B.en | C6: 0.062802614
A7: Qwen3-14B.tr | B7: Qwen3-4B.en | C7: -0.065068165
A8: Qwen3-14B.tr | B8: Qwen3-8B.en | C8: -0.10722961
A9: Qwen3-14B.cn | B9: Qwen3-8B.en | C9: -0.12706842
A10: Qwen3-14B.en | B10: Qwen3-8B.en | C10: -0.14272025
A11: Qwen3-4B.en | B11: Qwen3-8B.en | C11: -0.31438269
A12: Qwen3-4B.tr | B12: Qwen3-8B.en | C12: -0.39879147
A13: Llama-3.2-1B.en | B13: Ministral-3-3B.en | C13: -0.55920034
A14: Qwen3-4B.cn | B14: Qwen3-8B.en | C14: -0.60876929
A15: Llama-3.2-1B.cn | B15: Llama-3.2-1B.en | C15: -0.68601578
A16: Llama-3.2-1B.en | B16: Ministral-3-8B.en | C16: -0.77846612
A17: Llama-3.2-1B.tr | B17: Ministral-3-3B.en | C17: -0.80024667
... A436: Qwen3-4B.cn | B436: gemma-3-12b.tr | C436: -5.1525605

Sheet Sankey Plots (N)
A1: Languages
B2: English | C2: Chinese | D2: Turkish
A3: # of invariable plots | B3: 4 | C3: 4 | D3: 2 | G3: In English and Chinese, all three Qwen models produced so-called "invariable" plots whereby the probability of model answering selected the same (or nearly the same) answer for all questions. The same was true in Turkish for all Qwen models except Qwen-8B
C30: Many of the Sankey plots also show inconsistency in operationalizing BFI-2 constructs. For instance, in this sample plot from Gemma-3-4B in English, following the track for Extraversion leads one down a path of mostly "4" responses overall, even though the meaning of some of the questions is reversed (i.e. One question may be "I have a lot of energy" and another may be "I am tired." To be consistently modeling for extraversion, the model should be selecting disagreements for these reverse questions, and oftentimes it is not. In this highlighted example, red circles mark positive responses for extraversion, yellow for neutral, and blue for negative. The overall picture is very inconsistent and given that very few paths lead up to "1" or "2", the other constructs are likely to be operationalized poorly as well.
